<?xml version="1.0"?>

<robot name="robot">
    <link name= "base_link">
        <visual>
            <geometry>
                <box size="0.5 0.3 0.2"/>
            </geometry>
            <material name="red">
                <color rgba="1.0 0 0 1"/>
            </material>
        </visual>
        <collision>
            <geometry>
                <box size="0.5 0.3 0.2"/>
            </geometry>
        </collision>
        <inertial>
            <mass value="1.0"/>
            <inertia ixx="0.015" iyy="0.0208" izz="0.0208" ixy="0" ixz="0" iyz="0"/>
        </inertial>
    </link>

    <link name="front_left_wheel">
        <visual>
            <geometry>
                <cylinder length="0.05" radius="0.1"/>
            </geometry>
            <material name="black">
                <color rgba="0 0 0 1"/>
            </material>
        </visual>
        <collision>
            <geometry>
                <cylinder length="0.05" radius="0.1"/>
            </geometry>
        </collision>
        <inertial>
            <mass value="0.1"/>
            <inertia ixx="0.00027" iyy="0.00027" izz="0.0005" ixy="0" ixz="0" iyz="0"/>
        </inertial>
    </link>

    <link name="front_right_wheel">
        <visual>
            <geometry>
                <cylinder length="0.05" radius="0.1"/>
            </geometry>
            <material name="black">
                <color rgba="0 0 0 1"/>
            </material>
        </visual>
        <collision>
            <geometry>
                <cylinder length="0.05" radius="0.1"/>
            </geometry>
        </collision>
        <inertial>
            <mass value="0.1"/>
            <inertia ixx="0.00027" iyy="0.00027" izz="0.0005" ixy="0" ixz="0" iyz="0"/>
        </inertial>
    </link>

    <link name="back_left_wheel">
        <visual>
            <geometry>
                <cylinder length="0.05" radius="0.1"/>
            </geometry>
            <material name="black">
                <color rgba="0 0 0 1"/>
            </material>
        </visual>
        <collision>
            <geometry>
                <cylinder length="0.05" radius="0.1"/>
            </geometry>
        </collision>
        <inertial>
            <mass value="0.1"/>
            <inertia ixx="0.00027" iyy="0.00027" izz="0.0005" ixy="0" ixz="0" iyz="0"/>
        </inertial>
    </link>

    <link name="back_right_wheel">
        <visual>
            <geometry>
                <cylinder length="0.05" radius="0.1"/>
            </geometry>
            <material name="black">
                <color rgba="0 0 0 1"/>
            </material>
        </visual>
        <collision>
            <geometry>
                <cylinder length="0.05" radius="0.1"/>
            </geometry>
        </collision>
        <inertial>
            <mass value="0.1"/>
            <inertia ixx="0.00027" iyy="0.00027" izz="0.0005" ixy="0" ixz="0" iyz="0"/>
        </inertial>
    </link>

    <joint name="front_left_wheel_joint" type="continuous">
        <axis xyz="0 0 1"/>
        <parent link="base_link"/>
        <child link="front_left_wheel"/>
        <origin rpy="-1.5708 0 0" xyz="0.15 0.175 -.085"/>
    </joint>

    <joint name="front_right_wheel_joint" type="continuous">
        <axis xyz="0 0 1"/>
        <parent link="base_link"/>
        <child link="front_right_wheel"/>
        <origin rpy="-1.5708 0 0" xyz="0.15 -0.175 -.085"/>
    </joint>

    <joint name="back_left_wheel_joint" type="continuous">
        <axis xyz="0 0 1"/>
        <parent link="base_link"/>
        <child link="back_left_wheel"/>
        <origin rpy="-1.5708 0 0" xyz="-0.15 0.175 -.085"/>
    </joint>

    <joint name="back_right_wheel_joint" type="continuous">
        <axis xyz="0 0 1"/>
        <parent link="base_link"/>
        <child link="back_right_wheel"/>
        <origin rpy="-1.5708 0 0" xyz="-0.15 -0.175 -.085"/>
    </joint>

    <link name= "lidar_link">
        <visual>
            <geometry>
                <cylinder length="0.1" radius="0.05"/>
            </geometry>
            <material name="black">
                <color rgba="0 0 0 1"/>
            </material>
        </visual>
        <collision>
            <geometry>
                <cylinder length="0.1" radius="0.05"/>
            </geometry>
        </collision>
        <inertial>
            <mass value="1.0"/>
            <inertia ixx="0.0005" iyy="0.0005" izz="0.0005" ixy="0" ixz="0" iyz="0"/>
        </inertial>
    </link>

    <joint name="lidar_link_joint" type="fixed">
        <axis xyz="0 0 1"/>
        <parent link="base_link"/>
        <child link="lidar_link"/>
        <origin rpy="0 0 3.14" xyz="0 0 .15"/>
    </joint>

    <link name= "camera_link">
        <visual>
            <geometry>
                <box size="0.05 0.05 0.05"/>
            </geometry>
            <material name="black">
                <color rgba="0 0 0 1"/>
            </material>
        </visual>
        <collision>
            <geometry>
                <box size="0.05 0.05 0.05"/>
            </geometry>
        </collision>
        <inertial>
            <mass value="0"/>
            <inertia ixx="0" iyy="0" izz="0" ixy="0" ixz="0" iyz="0"/>
        </inertial>
    </link>

    <joint name="camera_link_joint" type="fixed">
        <axis xyz="0 0 1"/>
        <parent link="base_link"/>
        <child link="camera_link"/>
        <origin rpy="0 0 0" xyz="0.275 0 .075"/>
    </joint>

    <gazebo reference="base_link">
        <material>Gazebo/Red</material>
    </gazebo>
    <gazebo reference="front_left_wheel">
        <material>Gazebo/Black</material>
    </gazebo>
    <gazebo reference="front_right_wheel">
        <material>Gazebo/Black</material>
    </gazebo>
    <gazebo reference="back_left_wheel">
        <material>Gazebo/Black</material>
    </gazebo>
    <gazebo reference="back_right_wheel">
        <material>Gazebo/Black</material>
    </gazebo>
    <gazebo reference="lidar_link">
        <material>Gazebo/Black</material>
    </gazebo>
    <gazebo reference="camera_link">
        <material>Gazebo/Black</material>
    </gazebo>

    <gazebo>
        <plugin name="skid_steer_drive_controller" filename="libgazebo_ros_skid_steer_drive.so">
            <updateRate>100.0</updateRate>
            <robotNamespace>/</robotNamespace>
            <leftFrontJoint>front_left_wheel_joint</leftFrontJoint>
            <rightFrontJoint>front_right_wheel_joint</rightFrontJoint>
            <leftRearJoint>back_left_wheel_joint</leftRearJoint>
            <rightRearJoint>back_right_wheel_joint</rightRearJoint>
            <wheelSeparation>0.3</wheelSeparation>
            <wheelDiameter>0.2</wheelDiameter>
            <robotBaseFrame>base_link</robotBaseFrame>
            <torque>20</torque>
            <commandTopic >cmd_vel</commandTopic >
            <odometryTopic>odom</odometryTopic>
            <odometryFrame>odom</odometryFrame>
            <broadcastTF>true</broadcastTF>
            <!-- Set to true to publish transforms for the wheel links, defaults to false -->
            <publishWheelTF>true</publishWheelTF>
            <!-- Set to true to publish transforms for the odometry, defaults to true -->
            <publishOdom>true</publishOdom>
            <!-- Set to true to publish sensor_msgs/JointState on /joint_states for the wheel joints, defaults to false -->
            <publishWheelJointState>true</publishWheelJointState>
        </plugin>
    </gazebo>

    <gazebo reference="lidar_link">
        <sensor type="ray" name="head_hokuyo_sensor">
        <pose>0 0 0 0 0 0</pose>
        <visualize>false</visualize>
        <update_rate>40</update_rate>
        <ray>
            <scan>
                <horizontal>
                    <samples>720</samples>
                    <resolution>1</resolution>
                    <min_angle>-3.14</min_angle>
                    <max_angle>3.14</max_angle>
                </horizontal>
            </scan>
            <range>
                <min>0.25</min>
                <max>30.0</max>
                <resolution>0.01</resolution>
            </range>
            <noise>
                <type>gaussian</type>
                <mean>0.0</mean>
                <stddev>0.01</stddev>
            </noise>
        </ray>
            <plugin name="gazebo_ros_head_hokuyo_controller" filename="libgazebo_ros_laser.so">
                <topicName>/scan</topicName>
                <frameName>lidar_link</frameName>
            </plugin>
            </sensor>
    </gazebo>

    <gazebo reference="camera_link">
        <sensor type="camera" name="camera">
            <update_rate>30.0</update_rate>
            <camera name="head">
                <horizontal_fov>1.3962634</horizontal_fov>
                <image>
                    <width>800</width>
                    <height>800</height>
                    <format>R8G8B8</format>
                </image>
                    <clip>
                    <near>0.02</near>
                    <far>300</far>
                </clip>
                <noise>
                    <type>gaussian</type>
                    <mean>0.0</mean>
                    <stddev>0.007</stddev>
                </noise>
            </camera>
            <plugin name="camera_controller" filename="libgazebo_ros_camera.so">
                <alwaysOn>true</alwaysOn>
                <updateRate>0.0</updateRate>
                <cameraName>/camera</cameraName>
                <imageTopicName>image_raw</imageTopicName>
                <cameraInfoTopicName>camera_info</cameraInfoTopicName>
                <frameName>camera_optical_frame</frameName>
                <hackBaseline>0.07</hackBaseline>
                <distortionK1>0.0</distortionK1>
                <distortionK2>0.0</distortionK2>
                <distortionK3>0.0</distortionK3>
                <distortionT1>0.0</distortionT1>
                <distortionT2>0.0</distortionT2>
            </plugin>
        </sensor>
    </gazebo>

    <gazebo>
        <plugin name="joint_state_publisher" filename= "libgazebo_ros_joint_state_publisher.so">
        <jointName>front_left_wheel_joint, front_right_wheel_joint, back_left_wheel_joint, back_right_wheel_joint</jointName>
        </plugin>
    </gazebo>

</robot>